<?xml version="1.0" ?>
<!-- =================================================================================== -->
<!-- |    This document was autogenerated by xacro from mir_ur5.urdf.xacro             | -->
<!-- |    EDITING THIS FILE BY HAND IS NOT RECOMMENDED                                 | -->
<!-- =================================================================================== -->
<robot name="MiR200_UR5" xmlns:controller="http://playerstage.sourceforge.net/gazebo/xmlschema/#controller" xmlns:interface="http://playerstage.sourceforge.net/gazebo/xmlschema/#interface" xmlns:sensor="http://playerstage.sourceforge.net/gazebo/xmlschema/#sensor" xmlns:xacro="http://wiki.ros.org/xacro">
  <!--Include all needed urdf files-->
  <!-- <xacro:include filename="$(find mir_ur5_description)/urdf/mir_200_v1.urdf.xacro"/> -->
  <!-- common stuff -->
  <!-- <xacro:include filename="$(find ur_description)/urdf/common.gazebo.xacro" /> -->
  <!-- measured from model -->
  <link name="base_link">
    <visual>
      <geometry>
        <mesh filename="package://ur_description/meshes/ur3/visual/base.dae"/>
      </geometry>
      <material name="LightGrey">
        <color rgba="0.7 0.7 0.7 1.0"/>
      </material>
    </visual>
    <collision>
      <geometry>
        <mesh filename="package://ur_description/meshes/ur3/collision/base.stl"/>
      </geometry>
    </collision>
    <inertial>
      <mass value="2.0"/>
      <origin rpy="0 0 0" xyz="0.0 0.0 0.0"/>
      <inertia ixx="0.0030531654454" ixy="0.0" ixz="0.0" iyy="0.0030531654454" iyz="0.0" izz="0.005625"/>
    </inertial>
  </link>
  <joint name="shoulder_pan_joint" type="revolute">
    <parent link="base_link"/>
    <child link="shoulder_link"/>
    <origin rpy="0.0 0.0 0.0" xyz="0.0 0.0 0.1519"/>
    <axis xyz="0 0 1"/>
    <limit effort="330.0" lower="-3.14159265359" upper="3.14159265359" velocity="2.16"/>
    <dynamics damping="0.0" friction="0.0"/>
  </joint>
  <link name="shoulder_link">
    <visual>
      <geometry>
        <mesh filename="package://ur_description/meshes/ur3/visual/shoulder.dae"/>
      </geometry>
      <material name="LightGrey">
        <color rgba="0.7 0.7 0.7 1.0"/>
      </material>
    </visual>
    <collision>
      <geometry>
        <mesh filename="package://ur_description/meshes/ur3/collision/shoulder.stl"/>
      </geometry>
    </collision>
    <inertial>
      <mass value="2.0"/>
      <origin rpy="0 0 0" xyz="0.0 0.0 0.0"/>
      <inertia ixx="0.0080931634294" ixy="0.0" ixz="0.0" iyy="0.0080931634294" iyz="0.0" izz="0.005625"/>
    </inertial>
  </link>
  <joint name="shoulder_lift_joint" type="revolute">
    <parent link="shoulder_link"/>
    <child link="upper_arm_link"/>
    <origin rpy="0.0 1.57079632679 0.0" xyz="0.0 0.1198 0.0"/>
    <axis xyz="0 1 0"/>
    <limit effort="330.0" lower="-3.14159265359" upper="3.14159265359" velocity="2.16"/>
    <dynamics damping="0.0" friction="0.0"/>
  </joint>
  <link name="upper_arm_link">
    <visual>
      <geometry>
        <mesh filename="package://ur_description/meshes/ur3/visual/upperarm.dae"/>
      </geometry>
      <material name="LightGrey">
        <color rgba="0.7 0.7 0.7 1.0"/>
      </material>
    </visual>
    <collision>
      <geometry>
        <mesh filename="package://ur_description/meshes/ur3/collision/upperarm.stl"/>
      </geometry>
    </collision>
    <inertial>
      <mass value="3.42"/>
      <origin rpy="0 0 0" xyz="0.0 0.0 0.121825"/>
      <inertia ixx="0.0217284832211" ixy="0.0" ixz="0.0" iyy="0.0217284832211" iyz="0.0" izz="0.00961875"/>
    </inertial>
  </link>
  <joint name="elbow_joint" type="revolute">
    <parent link="upper_arm_link"/>
    <child link="forearm_link"/>
    <origin rpy="0.0 0.0 0.0" xyz="0.0 -0.0925 0.24365"/>
    <axis xyz="0 1 0"/>
    <limit effort="150.0" lower="-3.14159265359" upper="3.14159265359" velocity="3.15"/>
    <dynamics damping="0.0" friction="0.0"/>
  </joint>
  <link name="forearm_link">
    <visual>
      <geometry>
        <mesh filename="package://ur_description/meshes/ur3/visual/forearm.dae"/>
      </geometry>
      <material name="LightGrey">
        <color rgba="0.7 0.7 0.7 1.0"/>
      </material>
    </visual>
    <collision>
      <geometry>
        <mesh filename="package://ur_description/meshes/ur3/collision/forearm.stl"/>
      </geometry>
    </collision>
    <inertial>
      <mass value="1.26"/>
      <origin rpy="0 0 0" xyz="0.0 0.0 0.106625"/>
      <inertia ixx="0.00654680644378" ixy="0.0" ixz="0.0" iyy="0.00654680644378" iyz="0.0" izz="0.00354375"/>
    </inertial>
  </link>
  <joint name="wrist_1_joint" type="revolute">
    <parent link="forearm_link"/>
    <child link="wrist_1_link"/>
    <origin rpy="0.0 1.57079632679 0.0" xyz="0.0 0.0 0.21325"/>
    <axis xyz="0 1 0"/>
    <limit effort="54.0" lower="-3.14159265359" upper="3.14159265359" velocity="3.2"/>
    <dynamics damping="0.0" friction="0.0"/>
  </joint>
  <link name="wrist_1_link">
    <visual>
      <geometry>
        <mesh filename="package://ur_description/meshes/ur3/visual/wrist1.dae"/>
      </geometry>
      <material name="LightGrey">
        <color rgba="0.7 0.7 0.7 1.0"/>
      </material>
    </visual>
    <collision>
      <geometry>
        <mesh filename="package://ur_description/meshes/ur3/collision/wrist1.stl"/>
      </geometry>
    </collision>
    <inertial>
      <mass value="0.8"/>
      <origin rpy="0 0 0" xyz="0.0 0.08505 0.0"/>
      <inertia ixx="0.002084999166" ixy="0.0" ixz="0.0" iyy="0.002084999166" iyz="0.0" izz="0.00225"/>
    </inertial>
  </link>
  <joint name="wrist_2_joint" type="revolute">
    <parent link="wrist_1_link"/>
    <child link="wrist_2_link"/>
    <origin rpy="0.0 0.0 0.0" xyz="0.0 0.08505 0.0"/>
    <axis xyz="0 0 1"/>
    <limit effort="54.0" lower="-3.14159265359" upper="3.14159265359" velocity="3.2"/>
    <dynamics damping="0.0" friction="0.0"/>
  </joint>
  <link name="wrist_2_link">
    <visual>
      <geometry>
        <mesh filename="package://ur_description/meshes/ur3/visual/wrist2.dae"/>
      </geometry>
      <material name="LightGrey">
        <color rgba="0.7 0.7 0.7 1.0"/>
      </material>
    </visual>
    <collision>
      <geometry>
        <mesh filename="package://ur_description/meshes/ur3/collision/wrist2.stl"/>
      </geometry>
    </collision>
    <inertial>
      <mass value="0.8"/>
      <origin rpy="0 0 0" xyz="0.0 0.0 0.08535"/>
      <inertia ixx="0.002084999166" ixy="0.0" ixz="0.0" iyy="0.002084999166" iyz="0.0" izz="0.00225"/>
    </inertial>
  </link>
  <joint name="wrist_3_joint" type="revolute">
    <parent link="wrist_2_link"/>
    <child link="wrist_3_link"/>
    <origin rpy="0.0 0.0 0.0" xyz="0.0 0.0 0.08535"/>
    <axis xyz="0 1 0"/>
    <limit effort="54.0" lower="-3.14159265359" upper="3.14159265359" velocity="3.2"/>
    <dynamics damping="0.0" friction="0.0"/>
  </joint>
  <link name="wrist_3_link">
    <visual>
      <geometry>
        <mesh filename="package://ur_description/meshes/ur3/visual/wrist3.dae"/>
      </geometry>
      <material name="LightGrey">
        <color rgba="0.7 0.7 0.7 1.0"/>
      </material>
    </visual>
    <collision>
      <geometry>
        <mesh filename="package://ur_description/meshes/ur3/collision/wrist3.stl"/>
      </geometry>
    </collision>
    <inertial>
      <mass value="0.35"/>
      <origin rpy="1.57079632679 0 0" xyz="0.0 0.0619 0.0"/>
      <inertia ixx="0.00013626661216" ixy="0.0" ixz="0.0" iyy="0.00013626661216" iyz="0.0" izz="0.0001792"/>
    </inertial>
  </link>
  <gazebo reference="wrist_3_link">
    <kp value="0.0"/>
    <!--stiffness coefficient-->
    <kd value="1.0"/>
    <!--dampening coefficient  old: 0.0-->
    <minDepth value="0.2"/>
    <maxVel value="0"/>
  </gazebo>
  <joint name="ee_fixed_joint" type="fixed">
    <parent link="wrist_3_link"/>
    <child link="ee_link"/>
    <origin rpy="0.0 0.0 1.57079632679" xyz="0.0 0.0819 0.0"/>
  </joint>
  <link name="ee_link">
    <visual>
      <origin rpy="0 0 0" xyz="0 0 0"/>
      <geometry>
        <sphere radius="0.01"/>
      </geometry>
      <material name="white"/>
    </visual>
    <collision>
      <geometry>
        <box size="0.01 0.01 0.01"/>
      </geometry>
    </collision>
  </link>
  <gazebo reference="ee_link">
    <kp value="0.0"/>
    <!--stiffness-->
    <kd value="1.0"/>
    <!--damping-->
    <minDepth value="0.2"/>
    <maxVel value="0"/>
  </gazebo>
  <!-- <link name="${prefix}ee_link">
      <collision>
        <geometry>
          <box size="0.01 0.01 0.01"/>
        </geometry>
        <origin rpy="0 0 0" xyz="-0.01 0 0"/>
      </collision>
    </link> -->
  <transmission name="shoulder_pan_trans">
    <type>transmission_interface/SimpleTransmission</type>
    <joint name="shoulder_pan_joint">
      <hardwareInterface>hardware_interface/PositionJointInterface</hardwareInterface>
      <hardwareInterface>hardware_interface/VelocityJointInterface</hardwareInterface>
    </joint>
    <actuator name="shoulder_pan_motor">
      <mechanicalReduction>1</mechanicalReduction>
    </actuator>
  </transmission>
  <transmission name="shoulder_lift_trans">
    <type>transmission_interface/SimpleTransmission</type>
    <joint name="shoulder_lift_joint">
      <hardwareInterface>hardware_interface/PositionJointInterface</hardwareInterface>
      <hardwareInterface>hardware_interface/VelocityJointInterface</hardwareInterface>
    </joint>
    <actuator name="shoulder_lift_motor">
      <mechanicalReduction>1</mechanicalReduction>
    </actuator>
  </transmission>
  <transmission name="elbow_trans">
    <type>transmission_interface/SimpleTransmission</type>
    <joint name="elbow_joint">
      <hardwareInterface>hardware_interface/PositionJointInterface</hardwareInterface>
      <hardwareInterface>hardware_interface/VelocityJointInterface</hardwareInterface>
    </joint>
    <actuator name="elbow_motor">
      <mechanicalReduction>1</mechanicalReduction>
    </actuator>
  </transmission>
  <transmission name="wrist_1_trans">
    <type>transmission_interface/SimpleTransmission</type>
    <joint name="wrist_1_joint">
      <hardwareInterface>hardware_interface/PositionJointInterface</hardwareInterface>
      <hardwareInterface>hardware_interface/VelocityJointInterface</hardwareInterface>
    </joint>
    <actuator name="wrist_1_motor">
      <mechanicalReduction>1</mechanicalReduction>
    </actuator>
  </transmission>
  <transmission name="wrist_2_trans">
    <type>transmission_interface/SimpleTransmission</type>
    <joint name="wrist_2_joint">
      <hardwareInterface>hardware_interface/PositionJointInterface</hardwareInterface>
      <hardwareInterface>hardware_interface/VelocityJointInterface</hardwareInterface>
    </joint>
    <actuator name="wrist_2_motor">
      <mechanicalReduction>1</mechanicalReduction>
    </actuator>
  </transmission>
  <transmission name="wrist_3_trans">
    <type>transmission_interface/SimpleTransmission</type>
    <joint name="wrist_3_joint">
      <hardwareInterface>hardware_interface/PositionJointInterface</hardwareInterface>
      <hardwareInterface>hardware_interface/VelocityJointInterface</hardwareInterface>
    </joint>
    <actuator name="wrist_3_motor">
      <mechanicalReduction>1</mechanicalReduction>
    </actuator>
  </transmission>
  <gazebo reference="shoulder_link">
    <selfCollide>true</selfCollide>
  </gazebo>
  <gazebo reference="upper_arm_link">
    <selfCollide>true</selfCollide>
  </gazebo>
  <gazebo reference="forearm_link">
    <selfCollide>true</selfCollide>
  </gazebo>
  <gazebo reference="wrist_1_link">
    <selfCollide>true</selfCollide>
  </gazebo>
  <gazebo reference="wrist_3_link">
    <selfCollide>true</selfCollide>
  </gazebo>
  <gazebo reference="wrist_2_link">
    <selfCollide>true</selfCollide>
  </gazebo>
  <gazebo reference="ee_link">
    <selfCollide>true</selfCollide>
  </gazebo>
  <!-- ROS base_link to UR 'Base' Coordinates transform -->
  <link name="base"/>
  <joint name="base_link-base_fixed_joint" type="fixed">
    <!-- NOTE: this rotation is only needed as long as base_link itself is
                 not corrected wrt the real robot (ie: rotated over 180
                 degrees)
      -->
    <origin rpy="0 0 -3.14159265359" xyz="0 0 0"/>
    <parent link="base_link"/>
    <child link="base"/>
  </joint>
  <!-- Frame coincident with all-zeros TCP on UR controller -->
  <!-- <link name="${prefix}tool0"/>
    <joint name="${prefix}wrist_3_link-tool0_fixed_joint" type="fixed">
      <origin xyz="0 ${wrist_3_length} 0" rpy="${pi/-2.0} 0 0"/>
      <parent link="${prefix}wrist_3_link"/>
      <child link="${prefix}tool0"/>
    </joint> -->
  <!-- Attach a sensor link -->
  <!-- <xacro:robotiq_ft300 parent="${prefix}tool0"  prefix="">
      <origin xyz="0 0 0 " rpy="0 0 0"/>
    </xacro:robotiq_ft300> -->
  <!-- <gazebo reference="ft300_sensor">
    <sensor type="contact" name="bumper">
        <update_rate>100.0</update_rate>
        <always_on>1</always_on>
        <visualize>true</visualize>
        <contact>
            <collision>wrist_3_link_fixed_joint_lump__ft300_sensor_collision_3</collision>
            <topic>/bumper_contact</topic>  
        </contact>
        <plugin name="gazebo_ros_bumper_controller" filename="libgazebo_ros_bumper.so">
             <alwaysOn>true</alwaysOn>
            <updateRate>100</updateRate>
            <bumperTopicName>/robot_bumper</bumperTopicName>
            <frameName>ft300_sensor</frameName>
        </plugin>
     </sensor>
  </gazebo>   -->
  <!-- <gazebo reference="${prefix}wrist_3_link-tool0_fixed_joint">
    <provideFeedback>true</provideFeedback>
    <disableFixedJointLumping>true</disableFixedJointLumping>
</gazebo>

 
<gazebo>
    <plugin name="ft_sensor" filename="libgazebo_ros_ft_sensor.so">
        <updateRate>100.0</updateRate>
        <topicName>ft_sensor_topic</topicName>
        <jointName>wrist_3_link-tool0_fixed_joint</jointName>
    </plugin>
</gazebo> -->
  <!--As MoveIt! seems to have difficulties with finding plans for the UR with full joint limits [-2pi, 2pi], 
  there is a joint_limited version using joint limits restricted to [-pi,pi]. In order to use this joint limited version set joint_limited="true"-->
  <!-- <link name="world" />

  <joint name="world_joint" type="fixed">
    <parent link="world" />
    <child link = "base_link_ur5" />
    <origin xyz="0.0 0.0 0.0" rpy="0.0 0.0 0.0" />
  </joint> -->
  <!-- <xacro:mir_200 prefix="$(arg tf_prefix)"/> -->
  <!--The position of the model was measured using laser scachild_frame="$(arg tf_prefix)wrist_3_link_ur5" nner. See Florian's master thesis-->
  <!-- <joint name="robot_to_ur5" type="fixed">
      <parent link="$(arg tf_prefix)base_link"/>
      <child link="$(arg tf_prefix)base_link_ur5"/>
      <origin xyz="0.244311 -0.140242 0.450477" rpy="0.0 0.0 0.0"/>
    </joint> -->
  <!--add force_torque sensor-->
  <!-- <xacro:include filename="$(find mir_ur5_description)/urdf/include/force_sensor.gazebo.xacro" />
    <xacro:sensor_force_torque joint_name="$(arg tf_prefix)wrist_3_joint" topic_name="ee_force_torque_sensor"/> old: $(arg tf_prefix)ee_link_ur5 -->
  <!--Link to Gazebo library-->
  <!-- <xacro:property name="joint_names" value="$(arg tf_prefix)shoulder_pan_joint $(arg tf_prefix)shoulder_lift_joint $(arg tf_prefix)elbow_joint $(arg tf_prefix)wrist_1_joint $(arg tf_prefix)wrist_2_joint $(arg tf_prefix)wrist_3_joint $(arg tf_prefix)tool_joint_ur5" /> -->
  <!-- old -->
  <!--<gazebo>
        <plugin name="gazebo_ros_control" filename="libgazebo_ros_control.so">
            <controlPeriod>0.001</controlPeriod>
            <legacyModeNS>true</legacyModeNS>
        </plugin>
    </gazebo>-->
  <!-- new -->
  <gazebo>
    <plugin filename="libhwi_switch_gazebo_ros_control.so" name="gazebo_ros_control">
      <!-- <robotNamespace>$(arg robot_namespace)</robotNamespace> -->
      <!--will be global namespace when not specified-->
      <controlPeriod>0.001</controlPeriod>
      <legacyModeNS>true</legacyModeNS>
      <!--<filterJointsParam>${joint_names}</filterJointsParam>-->
    </plugin>
  </gazebo>
  <!-- Either use the part in the <gazebo> tags or the following -->
  <!-- <xacro:diff_controller_plugin_gazebo prefix=""
        left_wheel_joint="left_wheel_joint"
        right_wheel_joint="right_wheel_joint"
        wheel_separation="${2*mir_200_act_wheel_dy}"
        wheel_radius="${mir_200_act_wheel_radius}"/> -->
</robot>

